Workbook

Sheet Leia-me
B1: Custo de transferência de arquivos: API Gateway x CloudFront
B3: Para que serve
B4: Estima o custo mensal de servir arquivos do S3 pelo padrão desta proposta (API Gateway REST -> S3, com Lambda authorizer e download em blocos) comparado a uma CDN (CloudFront sob demanda e planos de preço fixo), a partir do volume medido em produção.
B6: Como usar
B7: 1. Aba Consumo: informe quantos dias o levantamento cobre (célula C2) e, por categoria de arquivo, downloads no período, tamanho médio, % com HEAD e % de requisições extras (retomadas/retries). Células amarelas com texto azul são entradas. As duas linhas preenchidas são exemplos: substitua pelos dados reais.
B8: 2. Aba Premissas: preços e parâmetros (texto azul). Ajuste se a região ou os preços forem outros (ex.: bucket/API em sa-east-1, usuários na América do Sul).
B9: 3. Aba Comparativo: resultado mensal, sem nada a preencher.
B11: Legenda
B12: Texto azul = entrada editável | Fundo amarelo = dado de produção a preencher | Texto preto = fórmula | Texto verde = referência a outra aba.
B14: Modelo de cálculo
B15: API Gateway: cada bloco é uma requisição (teto de 10 MB por resposta; bloco padrão de 8 MiB). Custo = requisições (faixas) + transferência para a internet (faixas) + GET/HEAD no S3 por requisição (sem cache) + Lambda authorizer nas requisições que não acertam o cache do authorizer.
B16: CloudFront sob demanda: sem teto de payload, então por padrão 1 requisição por arquivo (configurável). Custo = requisições e dados acima do free tier (dados em faixas) + GET no S3 só nos cache-miss. Transferência S3 -> CloudFront não é cobrada. Não inclui validação de token na borda.
... B28: Preço de referência us-east-1 / América do Norte, conferido em 2026-09-13. Confirmar na página antes de decidir.

Sheet Premissas
B1: Premissas e preços
B2: Preço de referência us-east-1 / América do Norte, conferido em 2026-09-13. Confirmar na página antes de decidir.
B4: Geral
B5: Dias por mês (para mensalizar o período medido) | C5: 30
B6: Tamanho do bloco no API Gateway (MiB) | C6: 8
B7: Downloads no CloudFront em 1 requisição por arquivo? (1 = sim, 0 = mesmos blocos do API Gateway) | C7: 1
B8: API Gateway: Lambda authorizer
B9: Taxa de acerto do cache do authorizer (0 a 1) | C9: 0.9
B10: Memória do authorizer (MB) | C10: 256
B11: Duração média do authorizer (ms) | C11: 100
B12: Lambda: preço por milhão de invocações ($) | C12: 0.2
B13: Lambda: preço por GB-segundo ($, x86) | C13: 1.66667e-05
B14: S3
B15: S3: GET/HEAD por 1.000 requisições ($) | C15: 0.0004
B16: CloudFront sob demanda
B17: Taxa de acerto do cache do CloudFront (0 a 1) | C17: 0.8
B18: Free tier de dados (GB/mês) | C18: 1024
B19: Free tier de requisições (por mês) | C19: 10000000
B20: Preço por 10.000 requisições HTTPS ($) | C20: 0.01
B22: API Gateway REST: requisições por mês (preço por milhão)
B23: Faixa | C23: De (milhões) | D23: Até (milhões) | E23: Preço ($)
B24: Primeiros 333 milhões | C24: 0 | D24: 333 | E24: 3.5
B25: Próximos 667 milhões | C25: 333 | D25: 1000 | E25: 2.8
B26: Próximos 19 bilhões | C26: 1000 | D26: 20000 | E26: 2.38
B27: Acima de 20 bilhões | C27: 20000 | D27: 1000000000000 | E27: 1.51
B28: Fonte: https://aws.amazon.com/api-gateway/pricing/. Última faixa com 'Até' = 1E+12 (sem limite).
B30: API Gateway: transferência para a internet por mês (preço por GB)
B31: Faixa | C31: De (GB) | D31: Até (GB) | E31: Preço ($)
B32: Primeiros 10 TB | C32: 0 | D32: 10240 | E32: 0.09
B33: Próximos 40 TB | C33: 10240 | D33: 51200 | E33: 0.085
B34: Próximos 100 TB | C34: 51200 | D34: 153600 | E34: 0.07
B35: Acima de 150 TB | C35: 153600 | D35: 1000000000000 | E35: 0.05
B36: Fonte: https://aws.amazon.com/api-gateway/pricing/ (mesma tabela de transferência do EC2, us-east-1). Última faixa com 'Até' = 1E+12 (sem limite).
B38: CloudFront sob demanda: transferência para a internet por mês (preço por GB, após free tier)
B39: Faixa | C39: De (GB) | D39: Até (GB) | E39: Preço ($)
B40: Primeiros 10 TB | C40: 0 | D40: 10240 | E40: 0.085
B41: Próximos 40 TB | C41: 10240 | D41: 51200 | E41: 0.08
B42: Próximos 100 TB | C42: 51200 | D42: 153600 | E42: 0.06
B43: Próximos 350 TB | C43: 153600 | D43: 512000 | E43: 0.04
B44: Próximos 524 TB | C44: 512000 | D44: 1048576 | E44: 0.03
...

Sheet Consumo
B1: Consumo medido em produção
B2: Dias cobertos pelo levantamento | C2: 1 | D2: Preencha as colunas amarelas (C a F). As linhas 5 e 6 são exemplos: substitua pelos dados reais.
B4: Categoria de arquivo | C4: Downloads no período | D4: Tamanho médio (MB) | E4: % downloads com HEAD | F4: % requisições extras (retomada/retry) | G4: GB transferidos no período | H4: Blocos por download (API GW) | I4: Requisições API GW no período | J4: Requisições CloudFront no período
B5: Imagens (exemplo) | C5: 50000 | D5: 0.2 | E5: 0 | F5: 0.02 | G5: =C5*D5/1024 -> 9.765625 | H5: =IF(D5>0,ROUNDUP(D5/Premissas!$C$6,0),0) -> 1 | I5: =C5*(H5+E5)*(1+F5) -> 51000 | J5: =C5*(IF(Premissas!$C$7=1,IF(D5>0,1,0),H5)+E5)*(1+F5) -> 51000
B6: APKs (exemplo) | C6: 500 | D6: 100 | E6: 1 | F6: 0.05 | G6: =C6*D6/1024 -> 48.828125 | H6: =IF(D6>0,ROUNDUP(D6/Premissas!$C$6,0),0) -> 13 | I6: =C6*(H6+E6)*(1+F6) -> 7350 | J6: =C6*(IF(Premissas!$C$7=1,IF(D6>0,1,0),H6)+E6)*(1+F6) -> 1050
G7: =C7*D7/1024 -> 0 | H7: =IF(D7>0,ROUNDUP(D7/Premissas!$C$6,0),0) -> 0 | I7: =C7*(H7+E7)*(1+F7) -> 0 | J7: =C7*(IF(Premissas!$C$7=1,IF(D7>0,1,0),H7)+E7)*(1+F7) -> 0
G8: =C8*D8/1024 -> 0 | H8: =IF(D8>0,ROUNDUP(D8/Premissas!$C$6,0),0) -> 0 | I8: =C8*(H8+E8)*(1+F8) -> 0 | J8: =C8*(IF(Premissas!$C$7=1,IF(D8>0,1,0),H8)+E8)*(1+F8) -> 0
G9: =C9*D9/1024 -> 0 | H9: =IF(D9>0,ROUNDUP(D9/Premissas!$C$6,0),0) -> 0 | I9: =C9*(H9+E9)*(1+F9) -> 0 | J9: =C9*(IF(Premissas!$C$7=1,IF(D9>0,1,0),H9)+E9)*(1+F9) -> 0
G10: =C10*D10/1024 -> 0 | H10: =IF(D10>0,ROUNDUP(D10/Premissas!$C$6,0),0) -> 0 | I10: =C10*(H10+E10)*(1+F10) -> 0 | J10: =C10*(IF(Premissas!$C$7=1,IF(D10>0,1,0),H10)+E10)*(1+F10) -> 0
G11: =C11*D11/1024 -> 0 | H11: =IF(D11>0,ROUNDUP(D11/Premissas!$C$6,0),0) -> 0 | I11: =C11*(H11+E11)*(1+F11) -> 0 | J11: =C11*(IF(Premissas!$C$7=1,IF(D11>0,1,0),H11)+E11)*(1+F11) -> 0
G12: =C12*D12/1024 -> 0 | H12: =IF(D12>0,ROUNDUP(D12/Premissas!$C$6,0),0) -> 0 | I12: =C12*(H12+E12)*(1+F12) -> 0 | J12: =C12*(IF(Premissas!$C$7=1,IF(D12>0,1,0),H12)+E12)*(1+F12) -> 0
G13: =C13*D13/1024 -> 0 | H13: =IF(D13>0,ROUNDUP(D13/Premissas!$C$6,0),0) -> 0 | I13: =C13*(H13+E13)*(1+F13) -> 0 | J13: =C13*(IF(Premissas!$C$7=1,IF(D13>0,1,0),H13)+E13)*(1+F13) -> 0
G14: =C14*D14/1024 -> 0 | H14: =IF(D14>0,ROUNDUP(D14/Premissas!$C$6,0),0) -> 0 | I14: =C14*(H14+E14)*(1+F14) -> 0 | J14: =C14*(IF(Premissas!$C$7=1,IF(D14>0,1,0),H14)+E14)*(1+F14) -> 0
G15: =C15*D15/1024 -> 0 | H15: =IF(D15>0,ROUNDUP(D15/Premissas!$C$6,0),0) -> 0 | I15: =C15*(H15+E15)*(1+F15) -> 0 | J15: =C15*(IF(Premissas!$C$7=1,IF(D15>0,1,0),H15)+E15)*(1+F15) -> 0
G16: =C16*D16/1024 -> 0 | H16: =IF(D16>0,ROUNDUP(D16/Premissas!$C$6,0),0) -> 0 | I16: =C16*(H16+E16)*(1+F16) -> 0 | J16: =C16*(IF(Premissas!$C$7=1,IF(D16>0,1,0),H16)+E16)*(1+F16) -> 0
G17: =C17*D17/1024 -> 0 | H17: =IF(D17>0,ROUNDUP(D17/Premissas!$C$6,0),0) -> 0 | I17: =C17*(H17+E17)*(1+F17) -> 0 | J17: =C17*(IF(Premissas!$C$7=1,IF(D17>0,1,0),H17)+E17)*(1+F17) -> 0
G18: =C18*D18/1024 -> 0 | H18: =IF(D18>0,ROUNDUP(D18/Premissas!$C$6,0),0) -> 0 | I18: =C18*(H18+E18)*(1+F18) -> 0 | J18: =C18*(IF(Premissas!$C$7=1,IF(D18>0,1,0),H18)+E18)*(1+F18) -> 0
G19: =C19*D19/1024 -> 0 | H19: =IF(D19>0,ROUNDUP(D19/Premissas!$C$6,0),0) -> 0 | I19: =C19*(H19+E19)*(1+F19) -> 0 | J19: =C19*(IF(Premissas!$C$7=1,IF(D19>0,1,0),H19)+E19)*(1+F19) -> 0
B20: Total no período | C20: =SUM(C5:C19) -> 50500 | G20: =SUM(G5:G19) -> 58.59375 | I20: =SUM(I5:I19) -> 58350 | J20: =SUM(J5:J19) -> 52050
B22: Blocos por download = arredondamento para cima de tamanho / tamanho do bloco (Premissas). Requisições API GW = downloads × (blocos + % HEAD) × (1 + % extras). CloudFront usa 1 requisição por arquivo quando a premissa correspondente = 1.

Sheet Comparativo
B1: Comparativo mensal: API Gateway x CloudFront
B2: Tudo calculado a partir das abas Consumo e Premissas. Nada a preencher aqui.
B4: Volume mensal
B5: GB transferidos por mês | C5: =Consumo!$G$20*(Premissas!$C$5/Consumo!$C$2) -> 1757.8125 | D5: Consumo × dias por mês / dias medidos
B6: Requisições por mês no API Gateway | C6: =Consumo!$I$20*(Premissas!$C$5/Consumo!$C$2) -> 1750500
B7: Requisições por mês no CloudFront | C7: =Consumo!$J$20*(Premissas!$C$5/Consumo!$C$2) -> 1561500
B8: Downloads por mês | C8: =Consumo!$C$20*(Premissas!$C$5/Consumo!$C$2) -> 1515000
B10: API Gateway REST (padrão da proposta)
B11: Requisições | C11: =SUMPRODUCT((($C$6/1000000)>Premissas!$C$24:$C$27)*((($C$6/1000000)-Premissas!$C$24:$C$27)-(($C$6/1000000)>Premissas!$D$24:$D$27)*(($C$6/1000000)-Premissas!$D$24:$D$27))*Premissas!$E$24:$E$27) -> 6.12675 | D11: Faixas por milhão de requisições
B12: Transferência para a internet | C12: =SUMPRODUCT(($C$5>Premissas!$C$32:$C$35)*(($C$5-Premissas!$C$32:$C$35)-($C$5>Premissas!$D$32:$D$35)*($C$5-Premissas!$D$32:$D$35))*Premissas!$E$32:$E$35) -> 158.20312 | D12: Faixas por GB
B13: S3 GET/HEAD (toda requisição chega ao S3, sem cache) | C13: =$C$6/1000*Premissas!$C$15 -> 0.7002
B14: Lambda authorizer (requisições sem acerto de cache) | C14: =$C$6*(1-Premissas!$C$9)*(Premissas!$C$12/1000000+(Premissas!$C$10/1024)*(Premissas!$C$11/1000)*Premissas!$C$13) -> 0.10794765 | D14: Invocações + GB-segundos
B15: Total API Gateway | C15: =SUM(C11:C14) -> 165.13802
B17: CloudFront sob demanda (referência)
B18: Requisições (acima do free tier) | C18: =MAX(0,$C$7-Premissas!$C$19)/10000*Premissas!$C$20 -> 0
B19: Transferência para a internet (acima do free tier) | C19: =SUMPRODUCT((MAX(0,$C$5-Premissas!$C$18)>Premissas!$C$40:$C$45)*((MAX(0,$C$5-Premissas!$C$18)-Premissas!$C$40:$C$45)-(MAX(0,$C$5-Premissas!$C$18)>Premissas!$D$40:$D$45)*(MAX(0,$C$5-Premissas!$C$18)-Premissas!$D$40:$D$45))*Premissas!$E$40:$E$45) -> 62.374063 | D19: S3 -> CloudFront não é cobrado
B20: S3 GET (só cache-miss) | C20: =$C$7*(1-Premissas!$C$17)/1000*Premissas!$C$15 -> 0.12492
B21: Total CloudFront sob demanda | C21: =SUM(C18:C20) -> 62.498983
B23: CloudFront plano de preço fixo (referência)
B24: Menor plano que comporta o volume | C24: =IF(AND($C$7<=Premissas!$D$50,$C$5<=Premissas!$E$50),Premissas!$B$50,IF(AND($C$7<=Premissas!$D$51,$C$5<=Premissas!$E$51),Premissas!$B$51,IF(AND($C$7<=Premissas!$D$52,$C$5<=Premissas!$E$52),Premissas!$B$52,IF(AND($C$7<=Premissas!$D$53,$C$5<=Premissas!$E$53),Premissas!$B$53,"Excede os planos (usar sob demanda)")))) -> Pro | D24: Não verificado se o plano atende mTLS de viewer
B25: Custo do plano (ou sob demanda, se exceder) | C25: =IF(AND($C$7<=Premissas!$D$50,$C$5<=Premissas!$E$50),Premissas!$C$50,IF(AND($C$7<=Premissas!$D$51,$C$5<=Premissas!$E$51),Premissas!$C$51,IF(AND($C$7<=Premissas!$D$52,$C$5<=Premissas!$E$52),Premissas!$C$52,IF(AND($C$7<=Premissas!$D$53,$C$5<=Premissas!$E$53),Premissas!$C$53,$C$21)))) -> 15
B27: Diferença
B28: API Gateway − CloudFront sob demanda ($/mês) | C28: =C15-C21 -> 102.63904
B29: API Gateway / CloudFront sob demanda | C29: =IF(C21>0,C15/C21,"n/a (CloudFront dentro do free tier)") -> 2.6422514
B30: API Gateway − CloudFront plano fixo ($/mês) | C30: =C15-C25 -> 150.13802
B31: Custo por GB no API Gateway ($) | C31: =IF(C5>0,C15/C5,0) -> 0.093945186
B32: Custo por GB no CloudFront sob demanda ($) | C32: =IF(C5>0,C21/C5,0) -> 0.035554977
B33: Custo por download no API Gateway ($) | C33: =IF(C8>0,C15/C8,0) -> 0.000109002
B35: Leitura: o custo por GB transferido é equivalente nas duas opções sob demanda; a diferença vem de requisições por bloco, leituras no S3 sem cache e authorizer. Em volume alto, planos de preço fixo de CDN abrem distância, mas a variante CDN não atende hoje à validação online exigida pela governança (ADR 0001).
